Workbook

Sheet Budget total
A1: Budget total par candidat : péniche Freycinet
A2: Montants en euros. Prix demandés au 22 octobre 2026 ; aucun coût n'est estimé ici : les cases jaunes sont à remplir avec vos devis.
A3: Légende : texte bleu = donnée saisie ou reprise des annonces · texte noir = formule · texte vert = lien vers l'onglet Hypotheses · fond jaune = case à remplir.
A5: Poste | B5: Creil | C5: Saint-Mammès | D5: Arleux (Jessica) | E5: Saint-Jean-de-Losne | F5: Autre candidat | G5: Exemple de format (valeurs fictives, hors comparaison) | H5: Remarques
A6: 1. Rappel des annonces
A7: Lien de l'annonce | B7: nautisme/3243153381 | C7: nautisme/3253976756 | D7: nautisme/3132319776 | E7: nautisme/3265626787 | G7: (lien Leboncoin) | H7: Liens Leboncoin des annonces collées.
A8: Localisation | B8: Creil (Oise) | C8: Saint-Mammès (Seine-et-Marne), canal du Loing | D8: Arleux (Nord) | E8: Saint-Jean-de-Losne (Côte-d'Or), au port | G8: Ville (département) | H8: D'après les annonces.
A9: Titre / certificat de navigation | B9: Expiré depuis 2019 ; remise en conformité électrique nécessaire | C9: Non indiqué | D9: Certificat de l'Union annoncé valide jusqu'en 2029 | E9: Certificat communautaire annoncé valable jusqu'en 2030 | G9: Valide jusqu'en 20XX | H9: D'après les annonces ; à vérifier sur copie du certificat.
A10: Dernier sondage / cale sèche | B10: Plan de sondage 2024 ; doublage des bordés, bouchains et fond en 2024 | C10: Non indiqué | D10: Non indiqué (rapport à demander) | E10: Montée en cale juin 2023 ; rapport non précisé | G10: Année, épaisseurs | H10: Épaisseurs relevées : à demander à chaque vendeur.
A11: Emplacement / régime d'occupation | B11: Redevance sans titre (COSTU) à jour ; pas de COT | C11: Non indiqué | D11: Non indiqué | E11: Basé au port : régime à demander | G11: COT, contrat de port… | H11: La COT n'est pas cessible de plein droit : à négocier avec le gestionnaire (VNF ou HAROPA).
A12: Moteur / équipements marquants | B12: Baudouin DK6 fonctionnel ; cale aménagée en salle de réception | C12: Non indiqué ; cale lestée avec cornières pour un plancher | D12: Volvo 380 ch (8 800 h) ; pompe de ballast fixe de 100 t | E12: GM 92 de 365 ch (26 000 h) ; cales de 63 et 42 m² aménageables | G12: Moteur, heures | H12: D'après les annonces.
A13: 2. Achat
A14: Prix demandé (€) | B14: 48000 | C14: 70000 | D14: 70000 | E14: 90000 | G14: 50000 | H14: Creil : « à débattre » selon l'annonce. Prix demandés relevés le 22 octobre 2026.
A15: Prix visé après négociation (€) | G15: 45000 | H15: Laisser vide pour utiliser le prix demandé dans les calculs.
A16: Prix retenu pour le calcul (€) | B16: =IF(B15="",B14,B15) -> 48000 | C16: =IF(C15="",C14,C15) -> 70000 | D16: =IF(D15="",D14,D15) -> 70000 | E16: =IF(E15="",E14,E15) -> 90000 | F16: =IF(F15="",F14,F15) -> 0 | G16: =IF(G15="",G14,G15) -> 45000 | H16: Prix visé s'il est renseigné, sinon prix demandé.
A17: 3. Coûts à chiffrer avec des devis (€)
A18: Frais d'acte, courtier, immatriculation | G18: 1000 | H18: À l'achat.
A19: Expertise de coque indépendante (sondage ultrasons) | G19: 1000 | H19: Avant de signer. Conditionne le prêt et l'assurance.
A20: Déplacements et visites | G20: 1000 | H20: Avant l'achat ; les visites se font souvent le week-end.
A21: Assurance (première année) | G21: 1000 | H21: Peut exiger une expertise récente et un titre valide.
A22: Emplacement / redevance d'occupation (première année) | G22: 1000 | H22: COT non cessible : redevance à demander au gestionnaire ou au port.
A23: Convoyage vers l'emplacement | G23: 1000 | H23: Surtout pour Arleux et Saint-Jean-de-Losne, loin de l'Île-de-France.
A24: Mise en conformité électrique | G24: 1000 | H24: Creil : nécessaire pour renouveler le titre expiré depuis 2019.
A25: Titre de navigation / visite technique | G25: 1000 | H25: À renouveler selon les échéances annoncées.
A26: Cale sèche éventuelle | G26: 1000 | H26: Seulement si le sondage l'impose ; plusieurs bateaux annoncent une cale sèche ancienne.
A27: Révision moteur et groupe électrogène | G27: 1000 | H27: Saint-Jean-de-Losne : moteur à 26 000 h.
A28: Assainissement (eaux noires et grises) | G28: 1000 | H28: Saint-Jean-de-Losne : aucune cuve d'eaux noires annoncée. Lien avec le projet zéro-rejet.
A29: Aménagement, lestage, plancher de cale | G29: 1000 | H29: Saint-Mammès : cale déjà lestée avec cornières ; Saint-Jean-de-Losne : plan d'aménagement des cales en annexe.
A30: Autres postes | G30: 1000 | H30: À préciser.
A31: 4. Totaux
A32: Sous-total des coûts à chiffrer (€) | B32: =SUM(B18:B30) -> 0 | C32: =SUM(C18:C30) -> 0 | D32: =SUM(D18:D30) -> 0 | E32: =SUM(E18:E30) -> 0 | F32: =SUM(F18:F30) -> 0 | G32: =SUM(G18:G30) -> 13000 | H32: Somme des postes de la section 3.
A33: Imprévus (€) | B33: =Hypotheses!$B$5*B32 -> 0 | C33: =Hypotheses!$B$5*C32 -> 0 | D33: =Hypotheses!$B$5*D32 -> 0 | E33: =Hypotheses!$B$5*E32 -> 0 | F33: =Hypotheses!$B$5*F32 -> 0 | G33: =Hypotheses!$B$5*G32 -> 1950 | H33: Taux de l'onglet Hypotheses (15 %, source : Bible Technique 6.3) appliqué aux coûts à chiffrer, hors prix d'achat.
A34: TOTAL DU PROJET (€) | B34: =B16+B32+B33 -> 48000 | C34: =C16+C32+C33 -> 70000 | D34: =D16+D32+D33 -> 70000 | E34: =E16+E32+E33 -> 90000 | F34: =F16+F32+F33 -> 0 | G34: =G16+G32+G33 -> 59950 | H34: Prix retenu + coûts à chiffrer + imprévus. C'est le montant à présenter aux banques.
A35: Postes encore sans montant (nombre) | B35: =COUNTBLANK(B18:B30) -> 13 | C35: =COUNTBLANK(C18:C30) -> 13 | D35: =COUNTBLANK(D18:D30) -> 13 | E35: =COUNTBLANK(E18:E30) -> 13 | F35: =COUNTBLANK(F18:F30) -> 13 | G35: =COUNTBLANK(G18:G30) -> 0 | H35: Nombre de postes de la section 3 non renseignés : tant qu'il est supérieur à 0, le total est sous-estimé.
A36: 5. Financement
A37: Apport personnel (€) | G37: 1000 | H37: Saisi par vous.
A38: Prêt d'achat envisagé (€) | G38: 1000 | H38: Votre piste : un prêt d'achat proche de 50 000 € serait plus facile à obtenir (à valider avec les banques).
A39: Prêt travaux envisagé (€) | G39: 1000 | H39: Second prêt éventuel dédié aux travaux et à la mise en conformité.
A40: Total financé (€) | B40: =SUM(B37:B39) -> 0 | C40: =SUM(C37:C39) -> 0 | D40: =SUM(D37:D39) -> 0 | E40: =SUM(E37:E39) -> 0 | F40: =SUM(F37:F39) -> 0 | G40: =SUM(G37:G39) -> 3000 | H40: Apport + prêt d'achat + prêt travaux.
A41: Reste à financer (€) | B41: =B34-B40 -> 48000 | C41: =C34-C40 -> 70000 | D41: =D34-D40 -> 70000 | E41: =E34-E40 -> 90000 | F41: =F34-F40 -> 0 | G41: =G34-G40 -> 56950 | H41: Positif : il manque ce montant (en rouge) ; négatif : marge disponible.
...

Sheet Hypotheses
A1: Hypothèses du budget
A3: Hypothèse | B3: Valeur | C3: Source / remarque
A4: Seuil visé pour le prêt d'achat (€) | B4: 50000 | C4: Source : utilisateur, 17 octobre 2026. Ce seuil n'est pas un plafond ferme : à voir avec les banques.
A5: Taux d'imprévus appliqué aux coûts à chiffrer | B5: 0.15 | C5: Source : Bible Technique, section 6.3 (matrice de risques), « marge pour imprévus de 15 % ». Modifiable.
A6: Date des prix demandés | B6: 22 octobre 2026 | C6: Prix relevés dans les annonces Leboncoin collées par l'utilisateur ; ce sont des prix demandés, pas des prix de vente.

Sheet Banques
A1: Rendez-vous bancaires : grille de comparaison
A2: À remplir pendant les entretiens (deux établissements au moins, dont le Crédit Maritime). Les cases jaunes sont à saisir ; la colonne grise donne le format attendu (valeurs fictives).
A4: Critère | B4: Crédit Maritime | C4: Banque 2 | D4: Banque 3 | E4: Exemple de format (fictif)
A5: Type de prêt (personnel, affecté, crédit maritime) | E5: Prêt personnel
A6: Montant maximum pour un bateau (€) | E6: 40 000
A7: Taux nominal | E7: 4,0 %
A8: Durée maximale | E8: 7 ans
A9: Prêt d'achat et prêt travaux séparés possibles ? | E9: Oui / non
A10: Garantie demandée (hypothèque fluviale ou sans garantie sur le bateau) | E10: Sans garantie
A11: Documents exigés (expertise de coque, titre de navigation, assurance, emplacement) | E11: Liste des pièces
A12: Prêt possible sous condition d'expertise favorable ? | E12: Oui / non
A13: Frais de dossier et assurance emprunteur | E13: Montant ou %
A14: Délai de réponse | E14: 3 semaines
A15: Interlocuteur et date du rendez-vous | E15: Nom, JJ/MM/AAAA

Sheet Mode d'emploi
A1: Mode d'emploi
A3: À quoi sert ce classeur | B3: Comparer le coût total de quatre candidats (Creil, Saint-Mammès, Arleux, Saint-Jean-de-Losne) et préparer vos rendez-vous bancaires. Une colonne « Autre candidat » est libre.
A4: Ce que vous devez remplir | B4: Onglet « Budget total » : cases jaunes de la section 2 (prix visé), de la section 3 (devis) et de la section 5 (apport et prêts). Onglet « Banques » : cases jaunes pendant les entretiens. Onglet « Hypotheses » : seuil de prêt et taux d'imprévus, modifiables.
A5: Ce qui est calculé | B5: Prix retenu, sous-total, imprévus, total du projet, postes sans montant, total financé, reste à financer et test du seuil de 50 000 €. Ces cellules sont des formules : ne pas les écraser.
A6: Exemple de format | B6: La colonne grise « Exemple de format » de l'onglet Budget total utilise des valeurs fictives (1 000 € partout) uniquement pour montrer le format. Elle n'entre dans aucune comparaison.
A7: Origine des chiffres | B7: Les prix demandés viennent des annonces Leboncoin collées par l'utilisateur (relevés le 22 octobre 2026). Le taux d'imprévus de 15 % vient de la Bible Technique (section 6.3). Le seuil de 50 000 € vient de l'utilisateur. Aucun coût de travaux, d'expertise, d'assurance ou d'emplacement n'est estimé : ils doivent venir de devis.
A8: Limite importante | B8: Les prix sont des prix demandés, pas des prix de vente. Tant que des postes restent sans montant, le total du projet est sous-estimé. La COT n'est pas cessible de plein droit : le poste « emplacement » doit être confirmé auprès du gestionnaire avant de s'engager.
A9: Avertissement | B9: Ce tableau est un outil de préparation, pas un conseil financier ou juridique : les conditions de prêt sont à valider auprès des banques.
